Workbook

Sheet Lisez-moi
A1: Plan boule de neige — prop firms (bot 100 % automatique)
A3: Fichier conçu pour Google Sheets : Fichier > Importer > Importer les données. Toutes les cellules bleues de l'onglet Paramètres sont modifiables ; la Simulation et les Graphiques se recalculent automatiquement.
A5: ONGLETS
A6: Paramètres : rendement mensuel, capital de départ, part réinvestie, part trader par défaut.
A7: Données : la liste ordonnée des firmes à acheter — cycle CFD d'abord puis Futures, plans instant d'abord, du moins cher au plus cher. Capital cumulable max et prix de la composition la moins chère par firme.
A8: Simulation : un mois par ligne. Capital actif, profit brut, salaire net (après part firme), réinvesti, capital financé, répartition CFD / Futures, salaire net cumulé, trésorerie.
A9: Graphiques : capital financé, salaire mensuel brut et net, salaire net cumulé.
A11: MODÈLE
A12: Chaque mois : profit brut = capital financé × rendement. Salaire net = profit × part trader de chaque firme. Le salaire net réinvesti s'accumule et achète les firmes dans l'ordre de l'onglet Données, dès que la trésorerie suffit.
A13: Le nombre de firmes détenues chaque mois = nombre de firmes dont le prix cumulé est couvert par l'investi cumulé. Le capital financé en découle.
A15: LIMITES
A16: Borne théorique sous rendement constant, sans échec d'évaluation, drawdown, délai de payout ni plafond de retrait. Prix hors codes promo, à vérifier avant achat.

Sheet Paramètres
A1: Plan boule de neige — Paramètres
A3: Rendement mensuel brut du bot | B3: 0.1
A4: Capital de départ (FundedNext) | B4: 10000
A5: Part des gains réinvestie | B5: 1
A6: Part trader par défaut (si firme inconnue) | B6: 0.8
A7: Comptes achetés au maximum par mois | B7: 5
A9: Cellules bleues = à modifier. Tout le reste se recalcule (onglet Simulation).
A10: Modèle : départ FundedNext. Chaque mois profit = capital × rendement ; salaire net = profit × part trader.
A11: Le salaire net réinvesti achète les firmes dans l'ordre de l'onglet Données (CFD d'abord, instant d'abord, moins cher d'abord).

Sheet Données
A1: Ordre | B1: Cycle | C1: Prop firm | D1: Plan | E1: Capital ($) | F1: Prix ($) | G1: Part trader | H1: Capital × part | I1: Capital cumulé | J1: Capital×part cumulé | K1: Prix cumulé
A2: 1 | B2: CFD | C2: FundedHive | D2: Instant | E2: 1000000 | F2: 349 | G2: 0.99 | H2: =E2*G2 | I2: =E2 | J2: =H2 | K2: =F2
A3: 2 | B3: CFD | C3: Real Trader Fund | D3: Instant | E3: 100000 | F3: 360 | G3: 0.9 | H3: =E3*G3 | I3: =I2+E3 | J3: =J2+H3 | K3: =K2+F3
A4: 3 | B4: CFD | C4: Hydra Futures | D4: Instant | E4: 500000 | F4: 1980 | G4: 0.9 | H4: =E4*G4 | I4: =I3+E4 | J4: =J3+H4 | K4: =K3+F4
A5: 4 | B5: CFD | C5: XPIPS | D5: Instant | E5: 400000 | F5: 1596 | G5: 1 | H5: =E5*G5 | I5: =I4+E5 | J5: =J4+H5 | K5: =K4+F5
A6: 5 | B6: CFD | C6: Elysium Forex | D6: Instant | E6: 1000000 | F6: 4000 | G6: 0.9 | H6: =E6*G6 | I6: =I5+E6 | J6: =J5+H6 | K6: =K5+F6
A7: 6 | B7: CFD | C7: Alpine Funded | D7: Instant | E7: 200000 | F7: 839 | G7: 1 | H7: =E7*G7 | I7: =I6+E7 | J7: =J6+H7 | K7: =K6+F7
A8: 7 | B8: CFD | C8: Funding Pips | D8: Instant | E8: 300000 | F8: 1332 | G8: 1 | H8: =E8*G8 | I8: =I7+E8 | J8: =J7+H8 | K8: =K7+F8
A9: 8 | B9: CFD | C9: Hex Funded | D9: Instant | E9: 400000 | F9: 1908 | G9: 0.9 | H9: =E9*G9 | I9: =I8+E9 | J9: =J8+H9 | K9: =K8+F9
A10: 9 | B10: CFD | C10: FX2 Funding | D10: Instant | E10: 190000 | F10: 1055 | G10: 0.95 | H10: =E10*G10 | I10: =I9+E10 | J10: =J9+H10 | K10: =K9+F10
A11: 10 | B11: CFD | C11: Audacity Capital (FTP Instant Funding) | D11: Instant | E11: 240000 | F11: 1365 | G11: 0.8 | H11: =E11*G11 | I11: =I10+E11 | J11: =J10+H11 | K11: =K10+F11
A12: 11 | B12: CFD | C12: FundedForge | D12: Instant | E12: 100000 | F12: 650 | G12: 0.9 | H12: =E12*G12 | I12: =I11+E12 | J12: =J11+H12 | K12: =K11+F12
A13: 12 | B13: CFD | C13: We Copy Trade | D13: Instant | E13: 200000 | F13: 2000 | G13: 0.9 | H13: =E13*G13 | I13: =I12+E13 | J13: =J12+H13 | K13: =K12+F13
A14: 13 | B14: CFD | C14: BuoyTrade | D14: Instant | E14: 40000 | F14: 1980 | G14: 0.8 | H14: =E14*G14 | I14: =I13+E14 | J14: =J13+H14 | K14: =K13+F14
... A190: 189 | B190: Futures | C190: HyroTrader | D190: 2 étapes | E190: 200000 | F190: 999 | G190: 0.9 | H190: =E190*G190 | I190: =I189+E190 | J190: =J189+H190 | K190: =K189+F190

Sheet Simulation
A1: Mois | B1: Firmes au début | C1: Capital actif ($) | D1: Profit brut ($) | E1: Salaire net ($) | F1: Réinvesti ($) | G1: Investi cumulé ($) | H1: Firmes à la fin | I1: Capital financé ($) | J1: CFD ($) | K1: Futures ($) | L1: Salaire net cumulé ($) | M1: Trésorerie ($)
A2: 1 | B2: =IF(1=1,0,H1) | C2: =Paramètres!$B$4+IFERROR(INDEX(Données!$I$2:$I$190,$B2),0) | D2: =C2*Paramètres!$B$3 | E2: =(Paramètres!$B$4*Paramètres!$B$6+IFERROR(INDEX(Données!$J$2:$J$190,$B2),0))*Paramètres!$B$3 | F2: =E2*Paramètres!$B$5 | G2: =IF(1=1,F2,G1+F2) | H2: =MIN(189,$B2+Paramètres!$B$7,COUNTIF(Données!$K$2:$K$190,"<="&G2)) | I2: =Paramètres!$B$4+IFERROR(INDEX(Données!$I$2:$I$190,$H2),0) | J2: =Paramètres!$B$4+IFERROR(INDEX(Données!$I$2:$I$190,MIN($H2,160)),0) | K2: =I2-J2 | L2: =IF(1=1,E2,L1+E2) | M2: =G2-IFERROR(INDEX(Données!$K$2:$K$190,$H2),0)
A3: 2 | B3: =IF(2=1,0,H2) | C3: =Paramètres!$B$4+IFERROR(INDEX(Données!$I$2:$I$190,$B3),0) | D3: =C3*Paramètres!$B$3 | E3: =(Paramètres!$B$4*Paramètres!$B$6+IFERROR(INDEX(Données!$J$2:$J$190,$B3),0))*Paramètres!$B$3 | F3: =E3*Paramètres!$B$5 | G3: =IF(2=1,F3,G2+F3) | H3: =MIN(189,$B3+Paramètres!$B$7,COUNTIF(Données!$K$2:$K$190,"<="&G3)) | I3: =Paramètres!$B$4+IFERROR(INDEX(Données!$I$2:$I$190,$H3),0) | J3: =Paramètres!$B$4+IFERROR(INDEX(Données!$I$2:$I$190,MIN($H3,160)),0) | K3: =I3-J3 | L3: =IF(2=1,E3,L2+E3) | M3: =G3-IFERROR(INDEX(Données!$K$2:$K$190,$H3),0)
A4: 3 | B4: =IF(3=1,0,H3) | C4: =Paramètres!$B$4+IFERROR(INDEX(Données!$I$2:$I$190,$B4),0) | D4: =C4*Paramètres!$B$3 | E4: =(Paramètres!$B$4*Paramètres!$B$6+IFERROR(INDEX(Données!$J$2:$J$190,$B4),0))*Paramètres!$B$3 | F4: =E4*Paramètres!$B$5 | G4: =IF(3=1,F4,G3+F4) | H4: =MIN(189,$B4+Paramètres!$B$7,COUNTIF(Données!$K$2:$K$190,"<="&G4)) | I4: =Paramètres!$B$4+IFERROR(INDEX(Données!$I$2:$I$190,$H4),0) | J4: =Paramètres!$B$4+IFERROR(INDEX(Données!$I$2:$I$190,MIN($H4,160)),0) | K4: =I4-J4 | L4: =IF(3=1,E4,L3+E4) | M4: =G4-IFERROR(INDEX(Données!$K$2:$K$190,$H4),0)
A5: 4 | B5: =IF(4=1,0,H4) | C5: =Paramètres!$B$4+IFERROR(INDEX(Données!$I$2:$I$190,$B5),0) | D5: =C5*Paramètres!$B$3 | E5: =(Paramètres!$B$4*Paramètres!$B$6+IFERROR(INDEX(Données!$J$2:$J$190,$B5),0))*Paramètres!$B$3 | F5: =E5*Paramètres!$B$5 | G5: =IF(4=1,F5,G4+F5) | H5: =MIN(189,$B5+Paramètres!$B$7,COUNTIF(Données!$K$2:$K$190,"<="&G5)) | I5: =Paramètres!$B$4+IFERROR(INDEX(Données!$I$2:$I$190,$H5),0) | J5: =Paramètres!$B$4+IFERROR(INDEX(Données!$I$2:$I$190,MIN($H5,160)),0) | K5: =I5-J5 | L5: =IF(4=1,E5,L4+E5) | M5: =G5-IFERROR(INDEX(Données!$K$2:$K$190,$H5),0)
A6: 5 | B6: =IF(5=1,0,H5) | C6: =Paramètres!$B$4+IFERROR(INDEX(Données!$I$2:$I$190,$B6),0) | D6: =C6*Paramètres!$B$3 | E6: =(Paramètres!$B$4*Paramètres!$B$6+IFERROR(INDEX(Données!$J$2:$J$190,$B6),0))*Paramètres!$B$3 | F6: =E6*Paramètres!$B$5 | G6: =IF(5=1,F6,G5+F6) | H6: =MIN(189,$B6+Paramètres!$B$7,COUNTIF(Données!$K$2:$K$190,"<="&G6)) | I6: =Paramètres!$B$4+IFERROR(INDEX(Données!$I$2:$I$190,$H6),0) | J6: =Paramètres!$B$4+IFERROR(INDEX(Données!$I$2:$I$190,MIN($H6,160)),0) | K6: =I6-J6 | L6: =IF(5=1,E6,L5+E6) | M6: =G6-IFERROR(INDEX(Données!$K$2:$K$190,$H6),0)
A7: 6 | B7: =IF(6=1,0,H6) | C7: =Paramètres!$B$4+IFERROR(INDEX(Données!$I$2:$I$190,$B7),0) | D7: =C7*Paramètres!$B$3 | E7: =(Paramètres!$B$4*Paramètres!$B$6+IFERROR(INDEX(Données!$J$2:$J$190,$B7),0))*Paramètres!$B$3 | F7: =E7*Paramètres!$B$5 | G7: =IF(6=1,F7,G6+F7) | H7: =MIN(189,$B7+Paramètres!$B$7,COUNTIF(Données!$K$2:$K$190,"<="&G7)) | I7: =Paramètres!$B$4+IFERROR(INDEX(Données!$I$2:$I$190,$H7),0) | J7: =Paramètres!$B$4+IFERROR(INDEX(Données!$I$2:$I$190,MIN($H7,160)),0) | K7: =I7-J7 | L7: =IF(6=1,E7,L6+E7) | M7: =G7-IFERROR(INDEX(Données!$K$2:$K$190,$H7),0)
A8: 7 | B8: =IF(7=1,0,H7) | C8: =Paramètres!$B$4+IFERROR(INDEX(Données!$I$2:$I$190,$B8),0) | D8: =C8*Paramètres!$B$3 | E8: =(Paramètres!$B$4*Paramètres!$B$6+IFERROR(INDEX(Données!$J$2:$J$190,$B8),0))*Paramètres!$B$3 | F8: =E8*Paramètres!$B$5 | G8: =IF(7=1,F8,G7+F8) | H8: =MIN(189,$B8+Paramètres!$B$7,COUNTIF(Données!$K$2:$K$190,"<="&G8)) | I8: =Paramètres!$B$4+IFERROR(INDEX(Données!$I$2:$I$190,$H8),0) | J8: =Paramètres!$B$4+IFERROR(INDEX(Données!$I$2:$I$190,MIN($H8,160)),0) | K8: =I8-J8 | L8: =IF(7=1,E8,L7+E8) | M8: =G8-IFERROR(INDEX(Données!$K$2:$K$190,$H8),0)
A9: 8 | B9: =IF(8=1,0,H8) | C9: =Paramètres!$B$4+IFERROR(INDEX(Données!$I$2:$I$190,$B9),0) | D9: =C9*Paramètres!$B$3 | E9: =(Paramètres!$B$4*Paramètres!$B$6+IFERROR(INDEX(Données!$J$2:$J$190,$B9),0))*Paramètres!$B$3 | F9: =E9*Paramètres!$B$5 | G9: =IF(8=1,F9,G8+F9) | H9: =MIN(189,$B9+Paramètres!$B$7,COUNTIF(Données!$K$2:$K$190,"<="&G9)) | I9: =Paramètres!$B$4+IFERROR(INDEX(Données!$I$2:$I$190,$H9),0) | J9: =Paramètres!$B$4+IFERROR(INDEX(Données!$I$2:$I$190,MIN($H9,160)),0) | K9: =I9-J9 | L9: =IF(8=1,E9,L8+E9) | M9: =G9-IFERROR(INDEX(Données!$K$2:$K$190,$H9),0)
A10: 9 | B10: =IF(9=1,0,H9) | C10: =Paramètres!$B$4+IFERROR(INDEX(Données!$I$2:$I$190,$B10),0) | D10: =C10*Paramètres!$B$3 | E10: =(Paramètres!$B$4*Paramètres!$B$6+IFERROR(INDEX(Données!$J$2:$J$190,$B10),0))*Paramètres!$B$3 | F10: =E10*Paramètres!$B$5 | G10: =IF(9=1,F10,G9+F10) | H10: =MIN(189,$B10+Paramètres!$B$7,COUNTIF(Données!$K$2:$K$190,"<="&G10)) | I10: =Paramètres!$B$4+IFERROR(INDEX(Données!$I$2:$I$190,$H10),0) | J10: =Paramètres!$B$4+IFERROR(INDEX(Données!$I$2:$I$190,MIN($H10,160)),0) | K10: =I10-J10 | L10: =IF(9=1,E10,L9+E10) | M10: =G10-IFERROR(INDEX(Données!$K$2:$K$190,$H10),0)
A11: 10 | B11: =IF(10=1,0,H10) | C11: =Paramètres!$B$4+IFERROR(INDEX(Données!$I$2:$I$190,$B11),0) | D11: =C11*Paramètres!$B$3 | E11: =(Paramètres!$B$4*Paramètres!$B$6+IFERROR(INDEX(Données!$J$2:$J$190,$B11),0))*Paramètres!$B$3 | F11: =E11*Paramètres!$B$5 | G11: =IF(10=1,F11,G10+F11) | H11: =MIN(189,$B11+Paramètres!$B$7,COUNTIF(Données!$K$2:$K$190,"<="&G11)) | I11: =Paramètres!$B$4+IFERROR(INDEX(Données!$I$2:$I$190,$H11),0) | J11: =Paramètres!$B$4+IFERROR(INDEX(Données!$I$2:$I$190,MIN($H11,160)),0) | K11: =I11-J11 | L11: =IF(10=1,E11,L10+E11) | M11: =G11-IFERROR(INDEX(Données!$K$2:$K$190,$H11),0)
A12: 11 | B12: =IF(11=1,0,H11) | C12: =Paramètres!$B$4+IFERROR(INDEX(Données!$I$2:$I$190,$B12),0) | D12: =C12*Paramètres!$B$3 | E12: =(Paramètres!$B$4*Paramètres!$B$6+IFERROR(INDEX(Données!$J$2:$J$190,$B12),0))*Paramètres!$B$3 | F12: =E12*Paramètres!$B$5 | G12: =IF(11=1,F12,G11+F12) | H12: =MIN(189,$B12+Paramètres!$B$7,COUNTIF(Données!$K$2:$K$190,"<="&G12)) | I12: =Paramètres!$B$4+IFERROR(INDEX(Données!$I$2:$I$190,$H12),0) | J12: =Paramètres!$B$4+IFERROR(INDEX(Données!$I$2:$I$190,MIN($H12,160)),0) | K12: =I12-J12 | L12: =IF(11=1,E12,L11+E12) | M12: =G12-IFERROR(INDEX(Données!$K$2:$K$190,$H12),0)
A13: 12 | B13: =IF(12=1,0,H12) | C13: =Paramètres!$B$4+IFERROR(INDEX(Données!$I$2:$I$190,$B13),0) | D13: =C13*Paramètres!$B$3 | E13: =(Paramètres!$B$4*Paramètres!$B$6+IFERROR(INDEX(Données!$J$2:$J$190,$B13),0))*Paramètres!$B$3 | F13: =E13*Paramètres!$B$5 | G13: =IF(12=1,F13,G12+F13) | H13: =MIN(189,$B13+Paramètres!$B$7,COUNTIF(Données!$K$2:$K$190,"<="&G13)) | I13: =Paramètres!$B$4+IFERROR(INDEX(Données!$I$2:$I$190,$H13),0) | J13: =Paramètres!$B$4+IFERROR(INDEX(Données!$I$2:$I$190,MIN($H13,160)),0) | K13: =I13-J13 | L13: =IF(12=1,E13,L12+E13) | M13: =G13-IFERROR(INDEX(Données!$K$2:$K$190,$H13),0)
A14: 13 | B14: =IF(13=1,0,H13) | C14: =Paramètres!$B$4+IFERROR(INDEX(Données!$I$2:$I$190,$B14),0) | D14: =C14*Paramètres!$B$3 | E14: =(Paramètres!$B$4*Paramètres!$B$6+IFERROR(INDEX(Données!$J$2:$J$190,$B14),0))*Paramètres!$B$3 | F14: =E14*Paramètres!$B$5 | G14: =IF(13=1,F14,G13+F14) | H14: =MIN(189,$B14+Paramètres!$B$7,COUNTIF(Données!$K$2:$K$190,"<="&G14)) | I14: =Paramètres!$B$4+IFERROR(INDEX(Données!$I$2:$I$190,$H14),0) | J14: =Paramètres!$B$4+IFERROR(INDEX(Données!$I$2:$I$190,MIN($H14,160)),0) | K14: =I14-J14 | L14: =IF(13=1,E14,L13+E14) | M14: =G14-IFERROR(INDEX(Données!$K$2:$K$190,$H14),0)
A15: 14 | B15: =IF(14=1,0,H14) | C15: =Paramètres!$B$4+IFERROR(INDEX(Données!$I$2:$I$190,$B15),0) | D15: =C15*Paramètres!$B$3 | E15: =(Paramètres!$B$4*Paramètres!$B$6+IFERROR(INDEX(Données!$J$2:$J$190,$B15),0))*Paramètres!$B$3 | F15: =E15*Paramètres!$B$5 | G15: =IF(14=1,F15,G14+F15) | H15: =MIN(189,$B15+Paramètres!$B$7,COUNTIF(Données!$K$2:$K$190,"<="&G15)) | I15: =Paramètres!$B$4+IFERROR(INDEX(Données!$I$2:$I$190,$H15),0) | J15: =Paramètres!$B$4+IFERROR(INDEX(Données!$I$2:$I$190,MIN($H15,160)),0) | K15: =I15-J15 | L15: =IF(14=1,E15,L14+E15) | M15: =G15-IFERROR(INDEX(Données!$K$2:$K$190,$H15),0)
A16: 15 | B16: =IF(15=1,0,H15) | C16: =Paramètres!$B$4+IFERROR(INDEX(Données!$I$2:$I$190,$B16),0) | D16: =C16*Paramètres!$B$3 | E16: =(Paramètres!$B$4*Paramètres!$B$6+IFERROR(INDEX(Données!$J$2:$J$190,$B16),0))*Paramètres!$B$3 | F16: =E16*Paramètres!$B$5 | G16: =IF(15=1,F16,G15+F16) | H16: =MIN(189,$B16+Paramètres!$B$7,COUNTIF(Données!$K$2:$K$190,"<="&G16)) | I16: =Paramètres!$B$4+IFERROR(INDEX(Données!$I$2:$I$190,$H16),0) | J16: =Paramètres!$B$4+IFERROR(INDEX(Données!$I$2:$I$190,MIN($H16,160)),0) | K16: =I16-J16 | L16: =IF(15=1,E16,L15+E16) | M16: =G16-IFERROR(INDEX(Données!$K$2:$K$190,$H16),0)
A17: 16 | B17: =IF(16=1,0,H16) | C17: =Paramètres!$B$4+IFERROR(INDEX(Données!$I$2:$I$190,$B17),0) | D17: =C17*Paramètres!$B$3 | E17: =(Paramètres!$B$4*Paramètres!$B$6+IFERROR(INDEX(Données!$J$2:$J$190,$B17),0))*Paramètres!$B$3 | F17: =E17*Paramètres!$B$5 | G17: =IF(16=1,F17,G16+F17) | H17: =MIN(189,$B17+Paramètres!$B$7,COUNTIF(Données!$K$2:$K$190,"<="&G17)) | I17: =Paramètres!$B$4+IFERROR(INDEX(Données!$I$2:$I$190,$H17),0) | J17: =Paramètres!$B$4+IFERROR(INDEX(Données!$I$2:$I$190,MIN($H17,160)),0) | K17: =I17-J17 | L17: =IF(16=1,E17,L16+E17) | M17: =G17-IFERROR(INDEX(Données!$K$2:$K$190,$H17),0)
A18: 17 | B18: =IF(17=1,0,H17) | C18: =Paramètres!$B$4+IFERROR(INDEX(Données!$I$2:$I$190,$B18),0) | D18: =C18*Paramètres!$B$3 | E18: =(Paramètres!$B$4*Paramètres!$B$6+IFERROR(INDEX(Données!$J$2:$J$190,$B18),0))*Paramètres!$B$3 | F18: =E18*Paramètres!$B$5 | G18: =IF(17=1,F18,G17+F18) | H18: =MIN(189,$B18+Paramètres!$B$7,COUNTIF(Données!$K$2:$K$190,"<="&G18)) | I18: =Paramètres!$B$4+IFERROR(INDEX(Données!$I$2:$I$190,$H18),0) | J18: =Paramètres!$B$4+IFERROR(INDEX(Données!$I$2:$I$190,MIN($H18,160)),0) | K18: =I18-J18 | L18: =IF(17=1,E18,L17+E18) | M18: =G18-IFERROR(INDEX(Données!$K$2:$K$190,$H18),0)
A19: 18 | B19: =IF(18=1,0,H18) | C19: =Paramètres!$B$4+IFERROR(INDEX(Données!$I$2:$I$190,$B19),0) | D19: =C19*Paramètres!$B$3 | E19: =(Paramètres!$B$4*Paramètres!$B$6+IFERROR(INDEX(Données!$J$2:$J$190,$B19),0))*Paramètres!$B$3 | F19: =E19*Paramètres!$B$5 | G19: =IF(18=1,F19,G18+F19) | H19: =MIN(189,$B19+Paramètres!$B$7,COUNTIF(Données!$K$2:$K$190,"<="&G19)) | I19: =Paramètres!$B$4+IFERROR(INDEX(Données!$I$2:$I$190,$H19),0) | J19: =Paramètres!$B$4+IFERROR(INDEX(Données!$I$2:$I$190,MIN($H19,160)),0) | K19: =I19-J19 | L19: =IF(18=1,E19,L18+E19) | M19: =G19-IFERROR(INDEX(Données!$K$2:$K$190,$H19),0)
A20: 19 | B20: =IF(19=1,0,H19) | C20: =Paramètres!$B$4+IFERROR(INDEX(Données!$I$2:$I$190,$B20),0) | D20: =C20*Paramètres!$B$3 | E20: =(Paramètres!$B$4*Paramètres!$B$6+IFERROR(INDEX(Données!$J$2:$J$190,$B20),0))*Paramètres!$B$3 | F20: =E20*Paramètres!$B$5 | G20: =IF(19=1,F20,G19+F20) | H20: =MIN(189,$B20+Paramètres!$B$7,COUNTIF(Données!$K$2:$K$190,"<="&G20)) | I20: =Paramètres!$B$4+IFERROR(INDEX(Données!$I$2:$I$190,$H20),0) | J20: =Paramètres!$B$4+IFERROR(INDEX(Données!$I$2:$I$190,MIN($H20,160)),0) | K20: =I20-J20 | L20: =IF(19=1,E20,L19+E20) | M20: =G20-IFERROR(INDEX(Données!$K$2:$K$190,$H20),0)
A21: 20 | B21: =IF(20=1,0,H20) | C21: =Paramètres!$B$4+IFERROR(INDEX(Données!$I$2:$I$190,$B21),0) | D21: =C21*Paramètres!$B$3 | E21: =(Paramètres!$B$4*Paramètres!$B$6+IFERROR(INDEX(Données!$J$2:$J$190,$B21),0))*Paramètres!$B$3 | F21: =E21*Paramètres!$B$5 | G21: =IF(20=1,F21,G20+F21) | H21: =MIN(189,$B21+Paramètres!$B$7,COUNTIF(Données!$K$2:$K$190,"<="&G21)) | I21: =Paramètres!$B$4+IFERROR(INDEX(Données!$I$2:$I$190,$H21),0) | J21: =Paramètres!$B$4+IFERROR(INDEX(Données!$I$2:$I$190,MIN($H21,160)),0) | K21: =I21-J21 | L21: =IF(20=1,E21,L20+E21) | M21: =G21-IFERROR(INDEX(Données!$K$2:$K$190,$H21),0)
A22: 21 | B22: =IF(21=1,0,H21) | C22: =Paramètres!$B$4+IFERROR(INDEX(Données!$I$2:$I$190,$B22),0) | D22: =C22*Paramètres!$B$3 | E22: =(Paramètres!$B$4*Paramètres!$B$6+IFERROR(INDEX(Données!$J$2:$J$190,$B22),0))*Paramètres!$B$3 | F22: =E22*Paramètres!$B$5 | G22: =IF(21=1,F22,G21+F22) | H22: =MIN(189,$B22+Paramètres!$B$7,COUNTIF(Données!$K$2:$K$190,"<="&G22)) | I22: =Paramètres!$B$4+IFERROR(INDEX(Données!$I$2:$I$190,$H22),0) | J22: =Paramètres!$B$4+IFERROR(INDEX(Données!$I$2:$I$190,MIN($H22,160)),0) | K22: =I22-J22 | L22: =IF(21=1,E22,L21+E22) | M22: =G22-IFERROR(INDEX(Données!$K$2:$K$190,$H22),0)
A23: 22 | B23: =IF(22=1,0,H22) | C23: =Paramètres!$B$4+IFERROR(INDEX(Données!$I$2:$I$190,$B23),0) | D23: =C23*Paramètres!$B$3 | E23: =(Paramètres!$B$4*Paramètres!$B$6+IFERROR(INDEX(Données!$J$2:$J$190,$B23),0))*Paramètres!$B$3 | F23: =E23*Paramètres!$B$5 | G23: =IF(22=1,F23,G22+F23) | H23: =MIN(189,$B23+Paramètres!$B$7,COUNTIF(Données!$K$2:$K$190,"<="&G23)) | I23: =Paramètres!$B$4+IFERROR(INDEX(Données!$I$2:$I$190,$H23),0) | J23: =Paramètres!$B$4+IFERROR(INDEX(Données!$I$2:$I$190,MIN($H23,160)),0) | K23: =I23-J23 | L23: =IF(22=1,E23,L22+E23) | M23: =G23-IFERROR(INDEX(Données!$K$2:$K$190,$H23),0)
A24: 23 | B24: =IF(23=1,0,H23) | C24: =Paramètres!$B$4+IFERROR(INDEX(Données!$I$2:$I$190,$B24),0) | D24: =C24*Paramètres!$B$3 | E24: =(Paramètres!$B$4*Paramètres!$B$6+IFERROR(INDEX(Données!$J$2:$J$190,$B24),0))*Paramètres!$B$3 | F24: =E24*Paramètres!$B$5 | G24: =IF(23=1,F24,G23+F24) | H24: =MIN(189,$B24+Paramètres!$B$7,COUNTIF(Données!$K$2:$K$190,"<="&G24)) | I24: =Paramètres!$B$4+IFERROR(INDEX(Données!$I$2:$I$190,$H24),0) | J24: =Paramètres!$B$4+IFERROR(INDEX(Données!$I$2:$I$190,MIN($H24,160)),0) | K24: =I24-J24 | L24: =IF(23=1,E24,L23+E24) | M24: =G24-IFERROR(INDEX(Données!$K$2:$K$190,$H24),0)
A25: 24 | B25: =IF(24=1,0,H24) | C25: =Paramètres!$B$4+IFERROR(INDEX(Données!$I$2:$I$190,$B25),0) | D25: =C25*Paramètres!$B$3 | E25: =(Paramètres!$B$4*Paramètres!$B$6+IFERROR(INDEX(Données!$J$2:$J$190,$B25),0))*Paramètres!$B$3 | F25: =E25*Paramètres!$B$5 | G25: =IF(24=1,F25,G24+F25) | H25: =MIN(189,$B25+Paramètres!$B$7,COUNTIF(Données!$K$2:$K$190,"<="&G25)) | I25: =Paramètres!$B$4+IFERROR(INDEX(Données!$I$2:$I$190,$H25),0) | J25: =Paramètres!$B$4+IFERROR(INDEX(Données!$I$2:$I$190,MIN($H25,160)),0) | K25: =I25-J25 | L25: =IF(24=1,E25,L24+E25) | M25: =G25-IFERROR(INDEX(Données!$K$2:$K$190,$H25),0)
A26: 25 | B26: =IF(25=1,0,H25) | C26: =Paramètres!$B$4+IFERROR(INDEX(Données!$I$2:$I$190,$B26),0) | D26: =C26*Paramètres!$B$3 | E26: =(Paramètres!$B$4*Paramètres!$B$6+IFERROR(INDEX(Données!$J$2:$J$190,$B26),0))*Paramètres!$B$3 | F26: =E26*Paramètres!$B$5 | G26: =IF(25=1,F26,G25+F26) | H26: =MIN(189,$B26+Paramètres!$B$7,COUNTIF(Données!$K$2:$K$190,"<="&G26)) | I26: =Paramètres!$B$4+IFERROR(INDEX(Données!$I$2:$I$190,$H26),0) | J26: =Paramètres!$B$4+IFERROR(INDEX(Données!$I$2:$I$190,MIN($H26,160)),0) | K26: =I26-J26 | L26: =IF(25=1,E26,L25+E26) | M26: =G26-IFERROR(INDEX(Données!$K$2:$K$190,$H26),0)
A27: 26 | B27: =IF(26=1,0,H26) | C27: =Paramètres!$B$4+IFERROR(INDEX(Données!$I$2:$I$190,$B27),0) | D27: =C27*Paramètres!$B$3 | E27: =(Paramètres!$B$4*Paramètres!$B$6+IFERROR(INDEX(Données!$J$2:$J$190,$B27),0))*Paramètres!$B$3 | F27: =E27*Paramètres!$B$5 | G27: =IF(26=1,F27,G26+F27) | H27: =MIN(189,$B27+Paramètres!$B$7,COUNTIF(Données!$K$2:$K$190,"<="&G27)) | I27: =Paramètres!$B$4+IFERROR(INDEX(Données!$I$2:$I$190,$H27),0) | J27: =Paramètres!$B$4+IFERROR(INDEX(Données!$I$2:$I$190,MIN($H27,160)),0) | K27: =I27-J27 | L27: =IF(26=1,E27,L26+E27) | M27: =G27-IFERROR(INDEX(Données!$K$2:$K$190,$H27),0)
A28: 27 | B28: =IF(27=1,0,H27) | C28: =Paramètres!$B$4+IFERROR(INDEX(Données!$I$2:$I$190,$B28),0) | D28: =C28*Paramètres!$B$3 | E28: =(Paramètres!$B$4*Paramètres!$B$6+IFERROR(INDEX(Données!$J$2:$J$190,$B28),0))*Paramètres!$B$3 | F28: =E28*Paramètres!$B$5 | G28: =IF(27=1,F28,G27+F28) | H28: =MIN(189,$B28+Paramètres!$B$7,COUNTIF(Données!$K$2:$K$190,"<="&G28)) | I28: =Paramètres!$B$4+IFERROR(INDEX(Données!$I$2:$I$190,$H28),0) | J28: =Paramètres!$B$4+IFERROR(INDEX(Données!$I$2:$I$190,MIN($H28,160)),0) | K28: =I28-J28 | L28: =IF(27=1,E28,L27+E28) | M28: =G28-IFERROR(INDEX(Données!$K$2:$K$190,$H28),0)
A29: 28 | B29: =IF(28=1,0,H28) | C29: =Paramètres!$B$4+IFERROR(INDEX(Données!$I$2:$I$190,$B29),0) | D29: =C29*Paramètres!$B$3 | E29: =(Paramètres!$B$4*Paramètres!$B$6+IFERROR(INDEX(Données!$J$2:$J$190,$B29),0))*Paramètres!$B$3 | F29: =E29*Paramètres!$B$5 | G29: =IF(28=1,F29,G28+F29) | H29: =MIN(189,$B29+Paramètres!$B$7,COUNTIF(Données!$K$2:$K$190,"<="&G29)) | I29: =Paramètres!$B$4+IFERROR(INDEX(Données!$I$2:$I$190,$H29),0) | J29: =Paramètres!$B$4+IFERROR(INDEX(Données!$I$2:$I$190,MIN($H29,160)),0) | K29: =I29-J29 | L29: =IF(28=1,E29,L28+E29) | M29: =G29-IFERROR(INDEX(Données!$K$2:$K$190,$H29),0)
A30: 29 | B30: =IF(29=1,0,H29) | C30: =Paramètres!$B$4+IFERROR(INDEX(Données!$I$2:$I$190,$B30),0) | D30: =C30*Paramètres!$B$3 | E30: =(Paramètres!$B$4*Paramètres!$B$6+IFERROR(INDEX(Données!$J$2:$J$190,$B30),0))*Paramètres!$B$3 | F30: =E30*Paramètres!$B$5 | G30: =IF(29=1,F30,G29+F30) | H30: =MIN(189,$B30+Paramètres!$B$7,COUNTIF(Données!$K$2:$K$190,"<="&G30)) | I30: =Paramètres!$B$4+IFERROR(INDEX(Données!$I$2:$I$190,$H30),0) | J30: =Paramètres!$B$4+IFERROR(INDEX(Données!$I$2:$I$190,MIN($H30,160)),0) | K30: =I30-J30 | L30: =IF(29=1,E30,L29+E30) | M30: =G30-IFERROR(INDEX(Données!$K$2:$K$190,$H30),0)
A31: 30 | B31: =IF(30=1,0,H30) | C31: =Paramètres!$B$4+IFERROR(INDEX(Données!$I$2:$I$190,$B31),0) | D31: =C31*Paramètres!$B$3 | E31: =(Paramètres!$B$4*Paramètres!$B$6+IFERROR(INDEX(Données!$J$2:$J$190,$B31),0))*Paramètres!$B$3 | F31: =E31*Paramètres!$B$5 | G31: =IF(30=1,F31,G30+F31) | H31: =MIN(189,$B31+Paramètres!$B$7,COUNTIF(Données!$K$2:$K$190,"<="&G31)) | I31: =Paramètres!$B$4+IFERROR(INDEX(Données!$I$2:$I$190,$H31),0) | J31: =Paramètres!$B$4+IFERROR(INDEX(Données!$I$2:$I$190,MIN($H31,160)),0) | K31: =I31-J31 | L31: =IF(30=1,E31,L30+E31) | M31: =G31-IFERROR(INDEX(Données!$K$2:$K$190,$H31),0)
A32: 31 | B32: =IF(31=1,0,H31) | C32: =Paramètres!$B$4+IFERROR(INDEX(Données!$I$2:$I$190,$B32),0) | D32: =C32*Paramètres!$B$3 | E32: =(Paramètres!$B$4*Paramètres!$B$6+IFERROR(INDEX(Données!$J$2:$J$190,$B32),0))*Paramètres!$B$3 | F32: =E32*Paramètres!$B$5 | G32: =IF(31=1,F32,G31+F32) | H32: =MIN(189,$B32+Paramètres!$B$7,COUNTIF(Données!$K$2:$K$190,"<="&G32)) | I32: =Paramètres!$B$4+IFERROR(INDEX(Données!$I$2:$I$190,$H32),0) | J32: =Paramètres!$B$4+IFERROR(INDEX(Données!$I$2:$I$190,MIN($H32,160)),0) | K32: =I32-J32 | L32: =IF(31=1,E32,L31+E32) | M32: =G32-IFERROR(INDEX(Données!$K$2:$K$190,$H32),0)
A33: 32 | B33: =IF(32=1,0,H32) | C33: =Paramètres!$B$4+IFERROR(INDEX(Données!$I$2:$I$190,$B33),0) | D33: =C33*Paramètres!$B$3 | E33: =(Paramètres!$B$4*Paramètres!$B$6+IFERROR(INDEX(Données!$J$2:$J$190,$B33),0))*Paramètres!$B$3 | F33: =E33*Paramètres!$B$5 | G33: =IF(32=1,F33,G32+F33) | H33: =MIN(189,$B33+Paramètres!$B$7,COUNTIF(Données!$K$2:$K$190,"<="&G33)) | I33: =Paramètres!$B$4+IFERROR(INDEX(Données!$I$2:$I$190,$H33),0) | J33: =Paramètres!$B$4+IFERROR(INDEX(Données!$I$2:$I$190,MIN($H33,160)),0) | K33: =I33-J33 | L33: =IF(32=1,E33,L32+E33) | M33: =G33-IFERROR(INDEX(Données!$K$2:$K$190,$H33),0)
A34: 33 | B34: =IF(33=1,0,H33) | C34: =Paramètres!$B$4+IFERROR(INDEX(Données!$I$2:$I$190,$B34),0) | D34: =C34*Paramètres!$B$3 | E34: =(Paramètres!$B$4*Paramètres!$B$6+IFERROR(INDEX(Données!$J$2:$J$190,$B34),0))*Paramètres!$B$3 | F34: =E34*Paramètres!$B$5 | G34: =IF(33=1,F34,G33+F34) | H34: =MIN(189,$B34+Paramètres!$B$7,COUNTIF(Données!$K$2:$K$190,"<="&G34)) | I34: =Paramètres!$B$4+IFERROR(INDEX(Données!$I$2:$I$190,$H34),0) | J34: =Paramètres!$B$4+IFERROR(INDEX(Données!$I$2:$I$190,MIN($H34,160)),0) | K34: =I34-J34 | L34: =IF(33=1,E34,L33+E34) | M34: =G34-IFERROR(INDEX(Données!$K$2:$K$190,$H34),0)
A35: 34 | B35: =IF(34=1,0,H34) | C35: =Paramètres!$B$4+IFERROR(INDEX(Données!$I$2:$I$190,$B35),0) | D35: =C35*Paramètres!$B$3 | E35: =(Paramètres!$B$4*Paramètres!$B$6+IFERROR(INDEX(Données!$J$2:$J$190,$B35),0))*Paramètres!$B$3 | F35: =E35*Paramètres!$B$5 | G35: =IF(34=1,F35,G34+F35) | H35: =MIN(189,$B35+Paramètres!$B$7,COUNTIF(Données!$K$2:$K$190,"<="&G35)) | I35: =Paramètres!$B$4+IFERROR(INDEX(Données!$I$2:$I$190,$H35),0) | J35: =Paramètres!$B$4+IFERROR(INDEX(Données!$I$2:$I$190,MIN($H35,160)),0) | K35: =I35-J35 | L35: =IF(34=1,E35,L34+E35) | M35: =G35-IFERROR(INDEX(Données!$K$2:$K$190,$H35),0)
A36: 35 | B36: =IF(35=1,0,H35) | C36: =Paramètres!$B$4+IFERROR(INDEX(Données!$I$2:$I$190,$B36),0) | D36: =C36*Paramètres!$B$3 | E36: =(Paramètres!$B$4*Paramètres!$B$6+IFERROR(INDEX(Données!$J$2:$J$190,$B36),0))*Paramètres!$B$3 | F36: =E36*Paramètres!$B$5 | G36: =IF(35=1,F36,G35+F36) | H36: =MIN(189,$B36+Paramètres!$B$7,COUNTIF(Données!$K$2:$K$190,"<="&G36)) | I36: =Paramètres!$B$4+IFERROR(INDEX(Données!$I$2:$I$190,$H36),0) | J36: =Paramètres!$B$4+IFERROR(INDEX(Données!$I$2:$I$190,MIN($H36,160)),0) | K36: =I36-J36 | L36: =IF(35=1,E36,L35+E36) | M36: =G36-IFERROR(INDEX(Données!$K$2:$K$190,$H36),0)
A37: 36 | B37: =IF(36=1,0,H36) | C37: =Paramètres!$B$4+IFERROR(INDEX(Données!$I$2:$I$190,$B37),0) | D37: =C37*Paramètres!$B$3 | E37: =(Paramètres!$B$4*Paramètres!$B$6+IFERROR(INDEX(Données!$J$2:$J$190,$B37),0))*Paramètres!$B$3 | F37: =E37*Paramètres!$B$5 | G37: =IF(36=1,F37,G36+F37) | H37: =MIN(189,$B37+Paramètres!$B$7,COUNTIF(Données!$K$2:$K$190,"<="&G37)) | I37: =Paramètres!$B$4+IFERROR(INDEX(Données!$I$2:$I$190,$H37),0) | J37: =Paramètres!$B$4+IFERROR(INDEX(Données!$I$2:$I$190,MIN($H37,160)),0) | K37: =I37-J37 | L37: =IF(36=1,E37,L36+E37) | M37: =G37-IFERROR(INDEX(Données!$K$2:$K$190,$H37),0)
A38: 37 | B38: =IF(37=1,0,H37) | C38: =Paramètres!$B$4+IFERROR(INDEX(Données!$I$2:$I$190,$B38),0) | D38: =C38*Paramètres!$B$3 | E38: =(Paramètres!$B$4*Paramètres!$B$6+IFERROR(INDEX(Données!$J$2:$J$190,$B38),0))*Paramètres!$B$3 | F38: =E38*Paramètres!$B$5 | G38: =IF(37=1,F38,G37+F38) | H38: =MIN(189,$B38+Paramètres!$B$7,COUNTIF(Données!$K$2:$K$190,"<="&G38)) | I38: =Paramètres!$B$4+IFERROR(INDEX(Données!$I$2:$I$190,$H38),0) | J38: =Paramètres!$B$4+IFERROR(INDEX(Données!$I$2:$I$190,MIN($H38,160)),0) | K38: =I38-J38 | L38: =IF(37=1,E38,L37+E38) | M38: =G38-IFERROR(INDEX(Données!$K$2:$K$190,$H38),0)
A39: 38 | B39: =IF(38=1,0,H38) | C39: =Paramètres!$B$4+IFERROR(INDEX(Données!$I$2:$I$190,$B39),0) | D39: =C39*Paramètres!$B$3 | E39: =(Paramètres!$B$4*Paramètres!$B$6+IFERROR(INDEX(Données!$J$2:$J$190,$B39),0))*Paramètres!$B$3 | F39: =E39*Paramètres!$B$5 | G39: =IF(38=1,F39,G38+F39) | H39: =MIN(189,$B39+Paramètres!$B$7,COUNTIF(Données!$K$2:$K$190,"<="&G39)) | I39: =Paramètres!$B$4+IFERROR(INDEX(Données!$I$2:$I$190,$H39),0) | J39: =Paramètres!$B$4+IFERROR(INDEX(Données!$I$2:$I$190,MIN($H39,160)),0) | K39: =I39-J39 | L39: =IF(38=1,E39,L38+E39) | M39: =G39-IFERROR(INDEX(Données!$K$2:$K$190,$H39),0)
A40: 39 | B40: =IF(39=1,0,H39) | C40: =Paramètres!$B$4+IFERROR(INDEX(Données!$I$2:$I$190,$B40),0) | D40: =C40*Paramètres!$B$3 | E40: =(Paramètres!$B$4*Paramètres!$B$6+IFERROR(INDEX(Données!$J$2:$J$190,$B40),0))*Paramètres!$B$3 | F40: =E40*Paramètres!$B$5 | G40: =IF(39=1,F40,G39+F40) | H40: =MIN(189,$B40+Paramètres!$B$7,COUNTIF(Données!$K$2:$K$190,"<="&G40)) | I40: =Paramètres!$B$4+IFERROR(INDEX(Données!$I$2:$I$190,$H40),0) | J40: =Paramètres!$B$4+IFERROR(INDEX(Données!$I$2:$I$190,MIN($H40,160)),0) | K40: =I40-J40 | L40: =IF(39=1,E40,L39+E40) | M40: =G40-IFERROR(INDEX(Données!$K$2:$K$190,$H40),0)
...

Sheet Graphiques
A1: Graphiques (se redessinent avec les paramètres)
